Workbook

Sheet Cantidades de Obra
D1: CANTIDADES DE OBRA
H3: CONTROL DOCUMENTAL
D4: REFORMAS Y REMODELACIONES | H4: Código | I4: RYR-CO-005
D5: DISEÑAMOS, RENOVAMOS Y CONSTRUIMOS ESPACIOS QUE INSPIRAN | H5: Versión | I5: 1
H6: Fecha de Emisión | I6: 10/09/2026
H7: Página | I7: 1 de 1
A8: ID | B8: Capítulo | C8: Subcapítulo | D8: Código actividad | E8: Actividad específica | F8: Ubicación / Frente | G8: Plano / Detalle | H8: Rev. | I8: Unidad | J8: Largo | K8: Ancho | L8: Alto / Prof. | M8: Espesor | N8: N° elementos | O8: Repeticiones | P8: Factor | Q8: Deducción | R8: Desperdicio % | S8: Cantidad neta | T8: Cantidad final | U8: Fórmula / criterio | V8: Observación técnica | W8: Responsable | X8: Fecha | Y8: Estado
A9: MQ-001 | B9: PRELIMINARES | C9: Preliminares generales | D9: 01.01.01 | E9: Localización y Replanteo | I9: ml | J9: 0 | K9: 0 | L9: 0 | M9: 0 | N9: 1 | O9: 1 | P9: 1 | Q9: 0 | R9: 0 | S9: =IF(I9="","",ROUND(IF(OR(I9="m²",I9="m2"),J9*IF(K9=0,1,K9)*IF(N9=0,1,N9)*IF(O9=0,1,O9)*P9-Q9,IF(OR(I9="m³",I9="m3"),J9*K9*L9*IF(N9=0,1,N9)*IF(O9=0,1,O9)*P9-Q9,IF(OR(I9="ml",I9="ML"),J9*IF(N9=0,1,N9)*IF(O9=0,1,O9)*P9-Q9,IF(OR(I9="und",I9="UND"),IF(N9=0,1,N9)*IF(O9=0,1,O9)*P9-Q9,IF(I9="kg",J9*IF(N9=0,1,N9)*IF(O9=0,1,O9)*P9-Q9,0))))),3)) | T9: =IF(S9="","",ROUND(S9*(1+R9),3)) | U9: ml | Y9: Pendiente
A10: MQ-002 | B10: PRELIMINARES | C10: Preliminares generales | D10: 01.01.02 | E10: Cerramiento provisional de obra | I10: ml | J10: 0 | K10: 0 | L10: 0 | M10: 0 | N10: 1 | O10: 1 | P10: 1 | Q10: 0 | R10: 0 | S10: =IF(I10="","",ROUND(IF(OR(I10="m²",I10="m2"),J10*IF(K10=0,1,K10)*IF(N10=0,1,N10)*IF(O10=0,1,O10)*P10-Q10,IF(OR(I10="m³",I10="m3"),J10*K10*L10*IF(N10=0,1,N10)*IF(O10=0,1,O10)*P10-Q10,IF(OR(I10="ml",I10="ML"),J10*IF(N10=0,1,N10)*IF(O10=0,1,O10)*P10-Q10,IF(OR(I10="und",I10="UND"),IF(N10=0,1,N10)*IF(O10=0,1,O10)*P10-Q10,IF(I10="kg",J10*IF(N10=0,1,N10)*IF(O10=0,1,O10)*P10-Q10,0))))),3)) | T10: =IF(S10="","",ROUND(S10*(1+R10),3)) | U10: ml | Y10: Pendiente
A11: MQ-003 | B11: PRELIMINARES | C11: Preliminares generales | D11: 01.01.03 | E11: Instalación de campamento y oficinas provisionales | I11: m² | J11: 0 | K11: 0 | L11: 0 | M11: 0 | N11: 1 | O11: 1 | P11: 1 | Q11: 0 | R11: 0 | S11: =IF(I11="","",ROUND(IF(OR(I11="m²",I11="m2"),J11*IF(K11=0,1,K11)*IF(N11=0,1,N11)*IF(O11=0,1,O11)*P11-Q11,IF(OR(I11="m³",I11="m3"),J11*K11*L11*IF(N11=0,1,N11)*IF(O11=0,1,O11)*P11-Q11,IF(OR(I11="ml",I11="ML"),J11*IF(N11=0,1,N11)*IF(O11=0,1,O11)*P11-Q11,IF(OR(I11="und",I11="UND"),IF(N11=0,1,N11)*IF(O11=0,1,O11)*P11-Q11,IF(I11="kg",J11*IF(N11=0,1,N11)*IF(O11=0,1,O11)*P11-Q11,0))))),3)) | T11: =IF(S11="","",ROUND(S11*(1+R11),3)) | U11: m² | Y11: Pendiente
A12: MQ-004 | B12: PRELIMINARES | C12: Preliminares generales | D12: 01.01.04 | E12: Adecuación de área de almacenamiento | I12: m² | J12: 0 | K12: 0 | L12: 0 | M12: 0 | N12: 1 | O12: 1 | P12: 1 | Q12: 0 | R12: 0 | S12: =IF(I12="","",ROUND(IF(OR(I12="m²",I12="m2"),J12*IF(K12=0,1,K12)*IF(N12=0,1,N12)*IF(O12=0,1,O12)*P12-Q12,IF(OR(I12="m³",I12="m3"),J12*K12*L12*IF(N12=0,1,N12)*IF(O12=0,1,O12)*P12-Q12,IF(OR(I12="ml",I12="ML"),J12*IF(N12=0,1,N12)*IF(O12=0,1,O12)*P12-Q12,IF(OR(I12="und",I12="UND"),IF(N12=0,1,N12)*IF(O12=0,1,O12)*P12-Q12,IF(I12="kg",J12*IF(N12=0,1,N12)*IF(O12=0,1,O12)*P12-Q12,0))))),3)) | T12: =IF(S12="","",ROUND(S12*(1+R12),3)) | U12: m² | Y12: Pendiente
A13: MQ-005 | B13: PRELIMINARES | C13: Preliminares generales | D13: 01.01.05 | E13: Señalización preventiva e informativa de obra | I13: und | J13: 0 | K13: 0 | L13: 0 | M13: 0 | N13: 1 | O13: 1 | P13: 1 | Q13: 0 | R13: 0 | S13: =IF(I13="","",ROUND(IF(OR(I13="m²",I13="m2"),J13*IF(K13=0,1,K13)*IF(N13=0,1,N13)*IF(O13=0,1,O13)*P13-Q13,IF(OR(I13="m³",I13="m3"),J13*K13*L13*IF(N13=0,1,N13)*IF(O13=0,1,O13)*P13-Q13,IF(OR(I13="ml",I13="ML"),J13*IF(N13=0,1,N13)*IF(O13=0,1,O13)*P13-Q13,IF(OR(I13="und",I13="UND"),IF(N13=0,1,N13)*IF(O13=0,1,O13)*P13-Q13,IF(I13="kg",J13*IF(N13=0,1,N13)*IF(O13=0,1,O13)*P13-Q13,0))))),3)) | T13: =IF(S13="","",ROUND(S13*(1+R13),3)) | U13: und | Y13: Pendiente
A14: MQ-006 | B14: PRELIMINARES | C14: Preliminares generales | D14: 01.01.06 | E14: Instalaciones provisionales de agua y energía | I14: gl | J14: 0 | K14: 0 | L14: 0 | M14: 0 | N14: 1 | O14: 1 | P14: 1 | Q14: 0 | R14: 0 | S14: =IF(I14="","",ROUND(IF(OR(I14="m²",I14="m2"),J14*IF(K14=0,1,K14)*IF(N14=0,1,N14)*IF(O14=0,1,O14)*P14-Q14,IF(OR(I14="m³",I14="m3"),J14*K14*L14*IF(N14=0,1,N14)*IF(O14=0,1,O14)*P14-Q14,IF(OR(I14="ml",I14="ML"),J14*IF(N14=0,1,N14)*IF(O14=0,1,O14)*P14-Q14,IF(OR(I14="und",I14="UND"),IF(N14=0,1,N14)*IF(O14=0,1,O14)*P14-Q14,IF(I14="kg",J14*IF(N14=0,1,N14)*IF(O14=0,1,O14)*P14-Q14,0))))),3)) | T14: =IF(S14="","",ROUND(S14*(1+R14),3)) | U14: gl | Y14: Pendiente
A15: MQ-007 | B15: PRELIMINARES | C15: Preliminares generales | D15: 01.01.07 | E15: Protección de elementos existentes | I15: m² | J15: 0 | K15: 0 | L15: 0 | M15: 0 | N15: 1 | O15: 1 | P15: 1 | Q15: 0 | R15: 0 | S15: =IF(I15="","",ROUND(IF(OR(I15="m²",I15="m2"),J15*IF(K15=0,1,K15)*IF(N15=0,1,N15)*IF(O15=0,1,O15)*P15-Q15,IF(OR(I15="m³",I15="m3"),J15*K15*L15*IF(N15=0,1,N15)*IF(O15=0,1,O15)*P15-Q15,IF(OR(I15="ml",I15="ML"),J15*IF(N15=0,1,N15)*IF(O15=0,1,O15)*P15-Q15,IF(OR(I15="und",I15="UND"),IF(N15=0,1,N15)*IF(O15=0,1,O15)*P15-Q15,IF(I15="kg",J15*IF(N15=0,1,N15)*IF(O15=0,1,O15)*P15-Q15,0))))),3)) | T15: =IF(S15="","",ROUND(S15*(1+R15),3)) | U15: m² | Y15: Pendiente
A16: MQ-008 | B16: PRELIMINARES | C16: Preliminares generales | D16: 01.01.08 | E16: Desmonte y limpieza inicial | I16: m² | J16: 0 | K16: 0 | L16: 0 | M16: 0 | N16: 1 | O16: 1 | P16: 1 | Q16: 0 | R16: 0 | S16: =IF(I16="","",ROUND(IF(OR(I16="m²",I16="m2"),J16*IF(K16=0,1,K16)*IF(N16=0,1,N16)*IF(O16=0,1,O16)*P16-Q16,IF(OR(I16="m³",I16="m3"),J16*K16*L16*IF(N16=0,1,N16)*IF(O16=0,1,O16)*P16-Q16,IF(OR(I16="ml",I16="ML"),J16*IF(N16=0,1,N16)*IF(O16=0,1,O16)*P16-Q16,IF(OR(I16="und",I16="UND"),IF(N16=0,1,N16)*IF(O16=0,1,O16)*P16-Q16,IF(I16="kg",J16*IF(N16=0,1,N16)*IF(O16=0,1,O16)*P16-Q16,0))))),3)) | T16: =IF(S16="","",ROUND(S16*(1+R16),3)) | U16: m² | Y16: Pendiente
A17: MQ-009 | B17: PRELIMINARES | C17: Preliminares generales | D17: 01.01.09 | E17: Demoliciones preliminares | I17: m³ | J17: 0 | K17: 0 | L17: 0 | M17: 0 | N17: 1 | O17: 1 | P17: 1 | Q17: 0 | R17: 0 | S17: =IF(I17="","",ROUND(IF(OR(I17="m²",I17="m2"),J17*IF(K17=0,1,K17)*IF(N17=0,1,N17)*IF(O17=0,1,O17)*P17-Q17,IF(OR(I17="m³",I17="m3"),J17*K17*L17*IF(N17=0,1,N17)*IF(O17=0,1,O17)*P17-Q17,IF(OR(I17="ml",I17="ML"),J17*IF(N17=0,1,N17)*IF(O17=0,1,O17)*P17-Q17,IF(OR(I17="und",I17="UND"),IF(N17=0,1,N17)*IF(O17=0,1,O17)*P17-Q17,IF(I17="kg",J17*IF(N17=0,1,N17)*IF(O17=0,1,O17)*P17-Q17,0))))),3)) | T17: =IF(S17="","",ROUND(S17*(1+R17),3)) | U17: m³ | Y17: Pendiente
A18: MQ-010 | B18: MOVIMIENTO DE TIERRAS | C18: Excavaciones | D18: 02.01.01 | E18: Excavación manual en material común | I18: m³ | J18: 0 | K18: 0 | L18: 0 | M18: 0 | N18: 1 | O18: 1 | P18: 1 | Q18: 0 | R18: 0 | S18: =IF(I18="","",ROUND(IF(OR(I18="m²",I18="m2"),J18*IF(K18=0,1,K18)*IF(N18=0,1,N18)*IF(O18=0,1,O18)*P18-Q18,IF(OR(I18="m³",I18="m3"),J18*K18*L18*IF(N18=0,1,N18)*IF(O18=0,1,O18)*P18-Q18,IF(OR(I18="ml",I18="ML"),J18*IF(N18=0,1,N18)*IF(O18=0,1,O18)*P18-Q18,IF(OR(I18="und",I18="UND"),IF(N18=0,1,N18)*IF(O18=0,1,O18)*P18-Q18,IF(I18="kg",J18*IF(N18=0,1,N18)*IF(O18=0,1,O18)*P18-Q18,0))))),3)) | T18: =IF(S18="","",ROUND(S18*(1+R18),3)) | U18: m³ | Y18: Pendiente
A19: MQ-011 | B19: MOVIMIENTO DE TIERRAS | C19: Excavaciones | D19: 02.01.02 | E19: Excavación mecánica | I19: m³ | J19: 0 | K19: 0 | L19: 0 | M19: 0 | N19: 1 | O19: 1 | P19: 1 | Q19: 0 | R19: 0 | S19: =IF(I19="","",ROUND(IF(OR(I19="m²",I19="m2"),J19*IF(K19=0,1,K19)*IF(N19=0,1,N19)*IF(O19=0,1,O19)*P19-Q19,IF(OR(I19="m³",I19="m3"),J19*K19*L19*IF(N19=0,1,N19)*IF(O19=0,1,O19)*P19-Q19,IF(OR(I19="ml",I19="ML"),J19*IF(N19=0,1,N19)*IF(O19=0,1,O19)*P19-Q19,IF(OR(I19="und",I19="UND"),IF(N19=0,1,N19)*IF(O19=0,1,O19)*P19-Q19,IF(I19="kg",J19*IF(N19=0,1,N19)*IF(O19=0,1,O19)*P19-Q19,0))))),3)) | T19: =IF(S19="","",ROUND(S19*(1+R19),3)) | U19: m³ | Y19: Pendiente
A20: MQ-012 | B20: MOVIMIENTO DE TIERRAS | C20: Excavaciones | D20: 02.01.03 | E20: Excavación en roca | I20: m³ | J20: 0 | K20: 0 | L20: 0 | M20: 0 | N20: 1 | O20: 1 | P20: 1 | Q20: 0 | R20: 0 | S20: =IF(I20="","",ROUND(IF(OR(I20="m²",I20="m2"),J20*IF(K20=0,1,K20)*IF(N20=0,1,N20)*IF(O20=0,1,O20)*P20-Q20,IF(OR(I20="m³",I20="m3"),J20*K20*L20*IF(N20=0,1,N20)*IF(O20=0,1,O20)*P20-Q20,IF(OR(I20="ml",I20="ML"),J20*IF(N20=0,1,N20)*IF(O20=0,1,O20)*P20-Q20,IF(OR(I20="und",I20="UND"),IF(N20=0,1,N20)*IF(O20=0,1,O20)*P20-Q20,IF(I20="kg",J20*IF(N20=0,1,N20)*IF(O20=0,1,O20)*P20-Q20,0))))),3)) | T20: =IF(S20="","",ROUND(S20*(1+R20),3)) | U20: m³ | Y20: Pendiente
... A145: MQ-137 | B145: ASEO, ENTREGA Y CIERRE | C145: Entrega | D145: 20.02.02 | E145: Entrega, manuales y acta de recibo | I145: gl | J145: 0 | K145: 0 | L145: 0 | M145: 0 | N145: 1 | O145: 1 | P145: 1 | Q145: 0 | R145: 0 | S145: =IF(I145="","",ROUND(IF(OR(I145="m²",I145="m2"),J145*IF(K145=0,1,K145)*IF(N145=0,1,N145)*IF(O145=0,1,O145)*P145-Q145,IF(OR(I145="m³",I145="m3"),J145*K145*L145*IF(N145=0,1,N145)*IF(O145=0,1,O145)*P145-Q145,IF(OR(I145="ml",I145="ML"),J145*IF(N145=0,1,N145)*IF(O145=0,1,O145)*P145-Q145,IF(OR(I145="und",I145="UND"),IF(N145=0,1,N145)*IF(O145=0,1,O145)*P145-Q145,IF(I145="kg",J145*IF(N145=0,1,N145)*IF(O145=0,1,O145)*P145-Q145,0))))),3)) | T145: =IF(S145="","",ROUND(S145*(1+R145),3)) | U145: gl | Y145: Pendiente
A146: REV. 10/09/2026 | Y146: =I4

Sheet Dashboard
B1: REFORMAS Y REMODELACIONES
J3: CONTROL DOCUMENTAL
B4: REFORMAS Y REMODELACIONES | J4: Código | K4: RYR-CO-001
B5: DISEÑAMOS, RENOVAMOS Y CONSTRUIMOS ESPACIOS QUE INSPIRAN | J5: Versión | K5: 1
J6: Fecha de Emisión | K6: 10/09/2026
J7: Página | K7: 1 de 1
A8: CONTROL MAESTRO DE CANTIDADES DE OBRA — TODAS LAS ACTIVIDADES
A9: Catálogo detallado para medición: preliminares • tierras • cimentación • estructura • mampostería • cubiertas • acabados • instalaciones • exteriores • cierre
A10: ACTIVIDADES CATALOGADAS | D10: CANTIDADES CALCULADAS | G10: ACTIVIDADES APROBADAS | J10: PENDIENTES
A11: =COUNTA('Cantidades de Obra'!A9:A153) | D11: =COUNT('Cantidades de Obra'!T9:T153) | G11: =COUNTIF('Cantidades de Obra'!Y9:Y153,"Aprobada") | J11: =COUNTIF('Cantidades de Obra'!Y9:Y153,"Pendiente")
A13: CONTROL POR CAPÍTULO
A14: Capítulo | B14: Actividades | C14: Calculadas | D14: Pendientes
A15: PRELIMINARES | B15: =COUNTIF('Cantidades de Obra'!B:B,A15) | C15: =COUNTIFS('Cantidades de Obra'!B:B,A15,'Cantidades de Obra'!T:T,">0") | D15: =B15-C15
A16: MOVIMIENTO DE TIERRAS | B16: =COUNTIF('Cantidades de Obra'!B:B,A16) | C16: =COUNTIFS('Cantidades de Obra'!B:B,A16,'Cantidades de Obra'!T:T,">0") | D16: =B16-C16
A17: CIMENTACIONES | B17: =COUNTIF('Cantidades de Obra'!B:B,A17) | C17: =COUNTIFS('Cantidades de Obra'!B:B,A17,'Cantidades de Obra'!T:T,">0") | D17: =B17-C17
A18: ESTRUCTURA | B18: =COUNTIF('Cantidades de Obra'!B:B,A18) | C18: =COUNTIFS('Cantidades de Obra'!B:B,A18,'Cantidades de Obra'!T:T,">0") | D18: =B18-C18
A19: MAMPOSTERÍA | B19: =COUNTIF('Cantidades de Obra'!B:B,A19) | C19: =COUNTIFS('Cantidades de Obra'!B:B,A19,'Cantidades de Obra'!T:T,">0") | D19: =B19-C19
A20: CUBIERTAS | B20: =COUNTIF('Cantidades de Obra'!B:B,A20) | C20: =COUNTIFS('Cantidades de Obra'!B:B,A20,'Cantidades de Obra'!T:T,">0") | D20: =B20-C20
A21: IMPERMEABILIZACIONES | B21: =COUNTIF('Cantidades de Obra'!B:B,A21) | C21: =COUNTIFS('Cantidades de Obra'!B:B,A21,'Cantidades de Obra'!T:T,">0") | D21: =B21-C21
A22: PAÑETES Y REVOQUES | B22: =COUNTIF('Cantidades de Obra'!B:B,A22) | C22: =COUNTIFS('Cantidades de Obra'!B:B,A22,'Cantidades de Obra'!T:T,">0") | D22: =B22-C22
A23: PISOS Y ENCHAPES | B23: =COUNTIF('Cantidades de Obra'!B:B,A23) | C23: =COUNTIFS('Cantidades de Obra'!B:B,A23,'Cantidades de Obra'!T:T,">0") | D23: =B23-C23
A24: PINTURA | B24: =COUNTIF('Cantidades de Obra'!B:B,A24) | C24: =COUNTIFS('Cantidades de Obra'!B:B,A24,'Cantidades de Obra'!T:T,">0") | D24: =B24-C24
A25: CARPINTERÍA | B25: =COUNTIF('Cantidades de Obra'!B:B,A25) | C25: =COUNTIFS('Cantidades de Obra'!B:B,A25,'Cantidades de Obra'!T:T,">0") | D25: =B25-C25
A26: VIDRIOS | B26: =COUNTIF('Cantidades de Obra'!B:B,A26) | C26: =COUNTIFS('Cantidades de Obra'!B:B,A26,'Cantidades de Obra'!T:T,">0") | D26: =B26-C26
... A34: ASEO, ENTREGA Y CIERRE | B34: =COUNTIF('Cantidades de Obra'!B:B,A34) | C34: =COUNTIFS('Cantidades de Obra'!B:B,A34,'Cantidades de Obra'!T:T,">0") | D34: =B34-C34
A35: FLUJO DE TRABAJO RECOMENDADO
A36: 1. Seleccionar actividad específica.
A37: 2. Registrar ubicación y plano/revisión.
A38: 3. Medir dimensiones y número de elementos.
A39: 4. Registrar deducciones y desperdicio justificado.
A40: 5. Revisar cantidad neta y final.
A41: 6. Contrastar con presupuesto/APU y aprobar.
A42: NOTA: el catálogo reúne actividades típicas y debe adaptarse al alcance contractual de cada proyecto. No todas las partidas aplican a todas las obras. Antes de utilizar una cantidad en presupuesto, compras, actas o avance, verifique planos vigentes, especificaciones, APU y condiciones contractuales.
A45: REV. 10/09/2026 | L45: =K4

Sheet Cálculo Detallado
D1: CANTIDADES DE OBRA
H3: CONTROL DOCUMENTAL
D4: REFORMAS Y REMODELACIONES | H4: Código | I4: RYR-CO-006
D5: DISEÑAMOS, RENOVAMOS Y CONSTRUIMOS ESPACIOS QUE INSPIRAN | H5: Versión | I5: 1
H6: Fecha de Emisión | I6: 10/09/2026
H7: Página | I7: 1 de 1
A8: ID cálculo | B8: ID cantidad | C8: Código actividad | D8: Actividad | E8: Ubicación | F8: Plano | G8: Rev. | H8: Unidad | I8: Largo | J8: Ancho | K8: Alto/Prof. | L8: N° elementos | M8: Repeticiones | N8: Factor | O8: Deducción | P8: Desperdicio % | Q8: Cantidad neta | R8: Cantidad final | S8: Criterio matemático | T8: Fuente / soporte | U8: Observaciones

Sheet Catalogo de Actividades
C1: CATÁLOGO MAESTRO DE ACTIVIDADES
F3: CONTROL DOCUMENTAL
C4: REFORMAS Y REMODELACIONES | F4: Código | G4: RYR-CO-002
C5: DISEÑAMOS, RENOVAMOS Y CONSTRUIMOS ESPACIOS QUE INSPIRAN | F5: Versión | G5: 1
F6: Fecha de Emisión | G6: 10/09/2026
F7: Página | G7: 1 de 1
A8: CATÁLOGO MAESTRO DE ACTIVIDADES — REFORMAS Y REMODELACIONES
A10: CÓD. ACTIVIDAD | B10: SUBCAPÍTULO | C10: GRUPO | D10: ACTIVIDAD ESPECÍFICA | E10: UNIDAD | F10: MÉTODO SUGERIDO
A11: 01 | PRELIMINARES
A12: 01.01.01 | B12: Preliminares generales | C12: Localización y replanteo | D12: Replanteo general de ejes y niveles | E12: ml | F12: Longitud × N° elementos × repeticiones − deducciones
A13: 01.01.02 | B13: Preliminares generales | C13: Cerramiento provisional | D13: Cerramiento provisional de obra | E13: ml | F13: Longitud × N° elementos × repeticiones − deducciones
A14: 01.01.03 | B14: Preliminares generales | C14: Campamento | D14: Instalación de campamento y oficinas provisionales | E14: m² | F14: Largo × Ancho × N° elementos × repeticiones − deducciones
A15: 01.01.04 | B15: Preliminares generales | C15: Almacenamiento | D15: Adecuación de área de almacenamiento | E15: m² | F15: Largo × Ancho × N° elementos × repeticiones − deducciones
A16: 01.01.05 | B16: Preliminares generales | C16: Señalización | D16: Señalización preventiva e informativa de obra | E16: und | F16: N° elementos × repeticiones − deducciones
A17: 01.01.06 | B17: Preliminares generales | C17: Servicios provisionales | D17: Instalaciones provisionales de agua y energía | E17: gl | F17: Según alcance contractual / presupuesto
A18: 01.01.07 | B18: Preliminares generales | C18: Protecciones | D18: Protección de elementos existentes | E18: m² | F18: Largo × Ancho × N° elementos × repeticiones − deducciones
A19: 01.01.08 | B19: Preliminares generales | C19: Desmonte | D19: Desmonte y limpieza inicial | E19: m² | F19: Largo × Ancho × N° elementos × repeticiones − deducciones
A20: 01.01.09 | B20: Preliminares generales | C20: Demoliciones | D20: Demoliciones preliminares | E20: m³ | F20: Largo × Ancho × Alto/Prof. × N° elementos × repeticiones − deducciones
A21: 02 | MOVIMIENTO DE TIERRAS
A22: 02.01.01 | B22: Excavaciones | C22: Excavación manual | D22: Excavación manual en material común | E22: m³ | F22: Largo × Ancho × Alto/Prof. × N° elementos × repeticiones − deducciones
A23: 02.01.02 | B23: Excavaciones | C23: Excavación mecánica | D23: Excavación mecánica | E23: m³ | F23: Largo × Ancho × Alto/Prof. × N° elementos × repeticiones − deducciones
A24: 02.01.03 | B24: Excavaciones | C24: Excavación en roca | D24: Excavación en roca | E24: m³ | F24: Largo × Ancho × Alto/Prof. × N° elementos × repeticiones − deducciones
A25: 02.01.04 | B25: Excavaciones | C25: Perfilado | D25: Perfilado y conformación de excavaciones | E25: m² | F25: Largo × Ancho × N° elementos × repeticiones − deducciones
A26: 02.02.01 | B26: Rellenos | C26: Relleno seleccionado | D26: Relleno con material seleccionado compactado | E26: m³ | F26: Largo × Ancho × Alto/Prof. × N° elementos × repeticiones − deducciones
A27: 02.02.02 | B27: Rellenos | C27: Relleno material excavación | D27: Relleno con material proveniente de excavación | E27: m³ | F27: Largo × Ancho × Alto/Prof. × N° elementos × repeticiones − deducciones
A28: 02.02.03 | B28: Rellenos | C28: Subbase | D28: Suministro, extendido y compactación de subbase | E28: m³ | F28: Largo × Ancho × Alto/Prof. × N° elementos × repeticiones − deducciones
A29: 02.02.04 | B29: Rellenos | C29: Base granular | D29: Suministro, extendido y compactación de base granular | E29: m³ | F29: Largo × Ancho × Alto/Prof. × N° elementos × repeticiones − deducciones
A30: 02.03.01 | B30: Retiro | C30: Cargue | D30: Cargue de material sobrante | E30: m³ | F30: Largo × Ancho × Alto/Prof. × N° elementos × repeticiones − deducciones
A31: 02.03.02 | B31: Retiro | C31: Transporte | D31: Transporte de material sobrante | E31: m³ | F31: Largo × Ancho × Alto/Prof. × N° elementos × repeticiones − deducciones
A32: 02.03.03 | B32: Retiro | C32: Disposición | D32: Disposición final de sobrantes | E32: m³ | F32: Largo × Ancho × Alto/Prof. × N° elementos × repeticiones − deducciones
A33: 03 | CIMENTACIONES
A34: 03.01.01 | B34: Concreto | C34: Solados | D34: Concreto de limpieza / solado | E34: m³ | F34: Largo × Ancho × Alto/Prof. × N° elementos × repeticiones − deducciones
A35: 03.01.02 | B35: Concreto | C35: Zapatas | D35: Concreto para zapatas | E35: m³ | F35: Largo × Ancho × Alto/Prof. × N° elementos × repeticiones − deducciones
A36: 03.01.03 | B36: Concreto | C36: Vigas de cimentación | D36: Concreto para vigas de cimentación | E36: m³ | F36: Largo × Ancho × Alto/Prof. × N° elementos × repeticiones − deducciones
A37: 03.01.04 | B37: Concreto | C37: Losas de cimentación | D37: Concreto para losas de cimentación | E37: m³ | F37: Largo × Ancho × Alto/Prof. × N° elementos × repeticiones − deducciones
A38: 03.01.05 | B38: Concreto | C38: Pedestales | D38: Concreto para pedestales | E38: m³ | F38: Largo × Ancho × Alto/Prof. × N° elementos × repeticiones − deducciones
A39: 03.02.01 | B39: Acero | C39: Acero de refuerzo | D39: Acero de refuerzo en cimentación | E39: kg | F39: Peso/despiece × N° elementos × repeticiones
A40: 03.03.01 | B40: Formaleta | C40: Formaleta cimentación | D40: Formaleta para elementos de cimentación | E40: m² | F40: Largo × Ancho × N° elementos × repeticiones − deducciones
A41: 04 | ESTRUCTURA
A42: 04.01.01 | B42: Concreto | C42: Columnas | D42: Concreto para columnas | E42: m³ | F42: Largo × Ancho × Alto/Prof. × N° elementos × repeticiones − deducciones
...

Sheet Planos
D1: REGISTRO DE PLANOS Y REVISIONES
H3: CONTROL DOCUMENTAL
D4: REFORMAS Y REMODELACIONES | H4: Código | I4: RYR-CO-003
D5: DISEÑAMOS, RENOVAMOS Y CONSTRUIMOS ESPACIOS QUE INSPIRAN | H5: Versión | I5: 1
H6: Fecha de Emisión | I6: 10/09/2026
H7: Página | I7: 1 de 1
A8: Código plano | B8: Disciplina | C8: Título | D8: Revisión | E8: Fecha | F8: Estado | G8: Actividades relacionadas | H8: Responsable | I8: Observaciones
A9: ARQ-001 | B9: Arquitectura | C9: Planta general | D9: R01 | E9: 46266 | F9: Vigente | G9: Preliminares / mampostería / acabados | H9: Ing. Residente
A10: EST-101 | B10: Estructural | C10: Cimentación | D10: R02 | E10: 46254 | F10: Vigente | G10: Cimentaciones / estructura | H10: Ing. Residente
A11: HID-201 | B11: Hidrosanitaria | C11: Redes hidrosanitarias | D11: R01 | E11: 46262 | F11: Vigente | G11: Instalaciones hidrosanitarias | H11: Ing. Residente
A12: ELE-301 | B12: Eléctrica | C12: Fuerza e iluminación | D12: R01 | E12: 46267 | F12: Vigente | G12: Instalaciones eléctricas | H12: Ing. Residente
A13: REV. 10/09/2026 | I13: =I4

Sheet Instructivo
E1: INSTRUCTIVO DE USO
K3: CONTROL DOCUMENTAL
E4: REFORMAS Y REMODELACIONES | K4: Código | L4: RYR-CO-004
E5: DISEÑAMOS, RENOVAMOS Y CONSTRUIMOS ESPACIOS QUE INSPIRAN | K5: Versión | L5: 1
K6: Fecha de Emisión | L6: 10/09/2026
K7: Página | L7: 1 de 1
A8: REFORMAS Y REMODELACIONES — INSTRUCTIVO DE CANTIDADES
A9: 1. IDENTIFICAR
A10: Use el código y actividad específica del catálogo; defina ubicación/frente y plano/revisión.
A12: 2. MEDIR
A13: Ingrese solo las dimensiones aplicables a la actividad: largo, ancho, alto/profundidad, espesor y número de elementos.
A15: 3. REPETIR
A16: Use N° de elementos para componentes repetitivos y Repeticiones para módulos o conjuntos.
A18: 4. DEDUCIR
A19: Registre vanos, vacíos u otros descuentos en Deducción y explique el criterio.
A21: 5. DESPERDICIO
A22: Ingrese el porcentaje como decimal (5% = 0,05) solo si está técnicamente o contractualmente sustentado.
A24: 6. TRAZABILIDAD
... A31: Cambie el Estado a Aprobada solo después de la revisión técnica.
A33: REV. 10/09/2026 | M33: =L4
