Workbook

Sheet Ficha Técnica del Proyecto
B1: FICHA TÉCNICA DEL PROYECTO
D3: CONTROL DOCUMENTAL
B4: REFORMAS Y REMODELACIONES | D4: Código | E4: RYR-FT-001
B5: DISEÑAMOS, RENOVAMOS Y CONSTRUIMOS ESPACIOS QUE INSPIRAN | D5: Versión | E5: 1
D6: Fecha de Emisión | E6: 10/09/2026
D7: Página | E7: 1 de 1
A8: IDENTIFICACIÓN DEL PROYECTO
A9: Proyecto
A10: No de Contrato | C10: Fecha de Emisión
A11: Contratista
A12: Ubicación
A13: DATOS GENERALES DEL PROYECTO
A14: Número de pisos (torre) | C14: pisos
A15: Número de sótanos (parqueaderos) | C15: niveles
A16: Área del lote | C16: m²
A17: Área construida típica por piso | C17: m²
A18: Área construida - torre (12 pisos) | B18: =B14*B17 | C18: m²
A19: Área construida - sótanos (2 niveles) | C19: m²
A20: Área cubierta / cuarto de máquinas / tanques | C20: m²
A21: ÁREA TOTAL CONSTRUIDA | B21: =B18+B19+B20 | C21: m²
A22: Número de apartamentos | C22: und
A23: Área promedio por apartamento (vendible) | C23: m²
A24: Número de parqueaderos | C24: und
A25: Número de ascensores | C25: und
A26: Altura total aproximada (sótano a cubierta) | C26: m
A28: PARÁMETROS ECONÓMICOS DEL PRESUPUESTO
A29: Administración (A) | B29: 0.1 | C29: % s/costo directo
A30: Imprevistos (I) | B30: 0.04 | C30: % s/costo directo
A31: Utilidad (U) | B31: 0.12 | C31: % s/costo directo
A32: IVA sobre Utilidad | B32: 0.19 | C32: % s/utilidad (Ley 1943 / práctica AIU en Colombia)
A34: AIU TOTAL (A+I+U) | B34: =B29+B30+B31
A36: FUENTES Y NOTAS METODOLÓGICAS
A37: REV. 10/09/2026 | E37: =E4
A38: 1. Precios de referencia investigados para Bogotá D.C., 2026 (2° semestre). Son precios promedio de mercado; cada obra requiere cotización formal con proveedores.
A39: 2. Rango de costo directo de construcción en Bogotá 2026 según fuentes de mercado: $2.200.000 - $3.800.000 COP/m² (Aliados de Obras, 2026); promedio de estabilización Ene-Abr 2026: ~$3.050.000 COP/m².
A40: 3. Concreto 3000 PSI para estructura con formaletería: referencia ~$868.306 COP/m³ (Listado de Precios Unitarios, Secretaría de Infraestructura / Fidubogotá, ajustado a 2026).
A41: 4. Acero de refuerzo figurado e instalado: referencia ~$6.500-7.000 COP/kg (Comando Construcciones, 2026; incremento por alza del 23,7% en el SMMLV 2026 según DANE-ICOCED).
A42: 5. Ascensor eléctrico para edificio de 10+ pisos, alta velocidad, instalado: $450M-$750M COP por unidad (OTA Vertical, 2026). Se tomó valor medio.
A43: 6. Índice de Costos de la Construcción de Edificaciones (ICOCED-DANE): variación interanual ene.2025-ene.2026 de +8,7% en Bogotá, impulsada por incremento salarial.
A44: 7. AIU recomendado para edificaciones en Colombia: 25%-30% sobre costos directos (Administración 10-12%, Imprevistos 3-5%, Utilidad 10-15%). Se usó 26% (10%+4%+12%).
...

Sheet Presupuesto 
C1: PRESUPUESTO DE OBRA
E5: CONTROL DOCUMENTAL
C6: REFORMAS Y REMODELACIONES | E6: Código | F6: RYR-PP-001
C7: DISEÑAMOS, RENOVAMOS Y CONSTRUIMOS ESPACIOS QUE INSPIRAN | E7: Versión | F7: 1
E8: Fecha de Emisión | F8: 10/09/2026
E9: Página | F9: 1 de 1
A10: IDENTIFICACIÓN DE PROYECTO
A11: Bogotá D.C. - Precios de referencia de mercado 2026 - Valores en pesos colombianos (COP), sin decimales
A12: Proyecto | E12: Fecha de Emisión | F12: 10/09/2026
A13: Ítem | B13: Descripción | C13: Unidad | D13: Cantidad | E13: Precio Unitario | F13: Valor Total
A14: 1 | B14: PRELIMINARES
A15: 1.1 | B15: Localización y Replanteo | C15: M² | F15: =D15*E15
A16: 1.2 | B16: Cerramiento provisional de obra | C16: ML | F16: =D16*E16
A17: 1.3 | B17: Instalación de campamento y oficinas provisionales | C17: M² | F17: =D17*E17
A18: 1.4 | B18: Adecuación de área de almacenamiento | C18: M² | F18: =D18*E18
A19: 1.5 | B19: Señalización preventiva e informativa de obra | C19: UND | F19: =D19*E19
A20: 1.6 | B20: Instalaciones provisionales de agua y energía | C20: GL | F20: =D20*E20
A21: 1.7 | B21: Protección de elementos existentes | C21: M² | F21: =D21*E21
A22: 1.8 | B22: Desmonte y limpieza inicial | C22: M² | F22: =D22*E22
A23: 1.9 | B23: Demoliciones preliminares | C23: M³ | F23: =D23*E23
A24: 1.10 | B24: Desmantelamiento de estructuras metálicas existentes | C24: KG | F24: =D24*E24
B25: SUBTOTAL CAPÍTULO 1 - PRELIMINARES | F25: =SUM(F15:F24)
A27: 2 | B27: MOVIMIENTO DE TIERRAS
A28: 2.1 | B28: Excavación manual en material común | C28: M³ | F28: =D28*E28
A29: 2.2 | B29: Excavación mecánica | C29: M³ | F29: =D29*E29
A30: 2.3 | B30: Excavación en roca | C30: M³ | F30: =D30*E30
A31: 2.4 | B31: Perfilado y conformación de excavaciones | C31: M² | F31: =D31*E31
A32: 2.5 | B32: Relleno con material seleccionado compactado | C32: M³ | F32: =D32*E32
A33: 2.6 | B33: Relleno con material proveniente de excavación | C33: M³ | F33: =D33*E33
A34: 2.7 | B34: Suministro, extendido y compactación de subbase | C34: M³ | F34: =D34*E34
A35: 2.8 | B35: Suministro, extendido y compactación de base granular | C35: M³ | F35: =D35*E35
A36: 2.9 | B36: Cargue de material sobrante | C36: M³ | F36: =D36*E36
A37: 2.10 | B37: Transporte de material sobrante | C37: M³ | F37: =D37*E37
A38: 2.11 | B38: Disposición final de sobrantes | C38: M³ | F38: =D38*E38
B39: SUBTOTAL CAPÍTULO 2 - MOVIMIENTO DE TIERRAS | F39: =SUM(F28:F38)
A41: 3 | B41: CIMENTACIONES
A42: 3.1 | B42: Concreto de limpieza / solado | C42: M³ | F42: =D42*E42
A43: 3.2 | B43: Concreto para zapatas | C43: M³ | F43: =D43*E43
A44: 3.3 | B44: Concreto para vigas de cimentación | C44: M³ | F44: =D44*E44
A45: 3.4 | B45: Concreto para losas de cimentación | C45: M³ | F45: =D45*E45
...

Sheet Informe Mensual
E1: INFORME MENSUAL DE AVANCE DE OBRA
L7: CONTROL DOCUMENTAL
E8: REFORMAS Y REMODELACIONES | L8: Código | M8: RYR-IM-001
L9: Versión | M9: 1
E10: DISEÑAMOS, RENOVAMOS Y CONSTRUIMOS ESPACIOS QUE INSPIRAN. | L10: Fecha de Emisión | M10: 10/09/2026
L11: Página | M11: 1 de 1
A12: IDENTIFICACIÓN DEL INFORME Y DEL PROYECTO
A13: Proyecto
A14: No de Contrato | I14: Presupuesto Total del Contrato | L14: ='Presupuesto '!F249
A15: Contratista | E15: REFORMAS Y REMODELACIONES | I15: Mes
A16: Elaborado por | I16: Fecha de Emisión
A17: RESUMEN EJECUTIVO
A19: AVANCE TÉCNICO Y ECONÓMICO DEL PROYECTO (POR CAPÍTULO)
A20: AVANCE PROGRAMADO GLOBAL | D20: AVANCE REAL GLOBAL | G20: DIFERENCIA | J20: % EJECUTADO FINANCIERO
A21: =H62 | D21: =I62 | G21: =D21-A21 | J21: =IFERROR(J62/$L$14,0)
A22: AVANCE REAL ACUMULADO AL INICIO DEL PERÍODO (%) | F22: 0 | H22: AVANCE DE ESTE PERÍODO (%) | K22: =D21-F22
A23: CAPÍTULO | D23: PESO % | E23: PROG. % | F23: REAL % | G23: DIF. % | H23: PROG. POND. % | I23: REAL POND. % | J23: VALOR EJECUTADO ($)
A25: ='Presupuesto '!B14 | D25: ='Presupuesto '!F25/'Presupuesto '!$F$240 | G25: =F25-E25 | H25: =D25*E25 | I25: =D25*F25 | J25: =D25*$L$14*G25
A26: ='Presupuesto '!B27 | D26: ='Presupuesto '!F39/'Presupuesto '!$F$240 | G26: =F26-E26 | H26: =D26*E26 | I26: =D26*F26 | J26: =D26*$L$14*G26
A27: ='Presupuesto '!B41 | D27: ='Presupuesto '!F49/'Presupuesto '!$F$240 | G27: =F27-E27 | H27: =D27*E27 | I27: =D27*F27 | J27: =D27*$L$14*G27
A28: ='Presupuesto '!B51 | D28: ='Presupuesto '!F69/'Presupuesto '!$F$240 | G28: =F28-E28 | H28: =D28*E28 | I28: =D28*F28 | J28: =D28*$L$14*G28
A29: ='Presupuesto '!B64 | D29: ='Presupuesto '!F81/'Presupuesto '!$F$240 | G29: =F29-E29 | H29: =D29*E29 | I29: =D29*F29 | J29: =D29*$L$14*G29
A30: ='Presupuesto '!B76 | D30: ='Presupuesto '!F93/'Presupuesto '!$F$240 | G30: =F30-E30 | H30: =D30*E30 | I30: =D30*F30 | J30: =D30*$L$14*G30
A31: ='Presupuesto '!B88 | D31: ='Presupuesto '!F100/'Presupuesto '!$F$240 | G31: =F31-E31 | H31: =D31*E31 | I31: =D31*F31 | J31: =D31*$L$14*G31
A32: ='Presupuesto '!B95 | D32: ='Presupuesto '!F107/'Presupuesto '!$F$240 | G32: =F32-E32 | H32: =D32*E32 | I32: =D32*F32 | J32: =D32*$L$14*G32
A33: ='Presupuesto '!B101 | D33: ='Presupuesto '!F121/'Presupuesto '!$F$240 | G33: =F33-E33 | H33: =D33*E33 | I33: =D33*F33 | J33: =D33*$L$14*G33
A34: ='Presupuesto '!B115 | D34: ='Presupuesto '!F129/'Presupuesto '!$F$240 | G34: =F34-E34 | H34: =D34*E34 | I34: =D34*F34 | J34: =D34*$L$14*G34
A35: ='Presupuesto '!B125 | D35: ='Presupuesto '!F140/'Presupuesto '!$F$240 | G35: =F35-E35 | H35: =D35*E35 | I35: =D35*F35 | J35: =D35*$L$14*G35
A36: ='Presupuesto '!B136 | D36: ='Presupuesto '!F147/'Presupuesto '!$F$240 | G36: =F36-E36 | H36: =D36*E36 | I36: =D36*F36 | J36: =D36*$L$14*G36
A37: ='Presupuesto '!B143 | D37: ='Presupuesto '!F162/'Presupuesto '!$F$240 | G37: =F37-E37 | H37: =D37*E37 | I37: =D37*F37 | J37: =D37*$L$14*G37
A38: ='Presupuesto '!B158 | D38: ='Presupuesto '!F176/'Presupuesto '!$F$240 | G38: =F38-E38 | H38: =D38*E38 | I38: =D38*F38 | J38: =D38*$L$14*G38
A39: ='Presupuesto '!B172 | D39: ='Presupuesto '!F185/'Presupuesto '!$F$240 | G39: =F39-E39 | H39: =D39*E39 | I39: =D39*F39 | J39: =D39*$L$14*G39
A40: ='Presupuesto '!B181 | D40: ='Presupuesto '!F192/'Presupuesto '!$F$240 | G40: =F40-E40 | H40: =D40*E40 | I40: =D40*F40 | J40: =D40*$L$14*G40
A41: ='Presupuesto '!B188 | D41: ='Presupuesto '!F198/'Presupuesto '!$F$240 | G41: =F41-E41 | H41: =D41*E41 | I41: =D41*F41 | J41: =D41*$L$14*G41
A42: ='Presupuesto '!B194 | D42: ='Presupuesto '!F212/'Presupuesto '!$F$240 | G42: =F42-E42 | H42: =D42*E42 | I42: =D42*F42 | J42: =D42*$L$14*G42
A43: ='Presupuesto '!B208 | D43: ='Presupuesto '!F219/'Presupuesto '!$F$240 | G43: =F43-E43 | H43: =D43*E43 | I43: =D43*F43 | J43: =D43*$L$14*G43
A44: ='Presupuesto '!B215 | D44: ='Presupuesto '!F227/'Presupuesto '!$F$240 | G44: =F44-E44 | H44: =D44*E44 | I44: =D44*F44 | J44: =D44*$L$14*G44
A45: ='Presupuesto '!B223 | D45: ='Presupuesto '!F231/'Presupuesto '!$F$240 | G45: =F45-E45 | H45: =D45*E45 | I45: =D45*F45 | J45: =D45*$L$14*G45
A46: ='Presupuesto '!B227 | D46: ='Presupuesto '!F238/'Presupuesto '!$F$240 | G46: =F46-E46 | H46: =D46*E46 | I46: =D46*F46 | J46: =D46*$L$14*G46
G47: =F47-E47 | H47: =D47*E47 | I47: =D47*F47 | J47: =D47*$L$14*G47
...
